<?xml version="1.0" ?>
<!-- =================================================================================== -->
<!-- |    This document was autogenerated by xacro from cobotta_pro_900_visualization/urdf/cobotta_pro_900.xacro | -->
<!-- |    EDITING THIS FILE BY HAND IS NOT RECOMMENDED                                 | -->
<!-- =================================================================================== -->
<robot name="cobotta_pro_900">
  <link name="world"/>
  <joint name="joint_w" type="fixed">
    <parent link="world"/>
    <child link="base_link"/>
  </joint>

  <link name="base_link">
  </link>

  <link name="J1">
  </link>

  <joint name="joint_1" type="revolute">
    <parent link="base_link"/>
    <child link="J1"/>
    <origin rpy="0.000000 0.000000 0.000000" xyz="0.000000 0.000000 0.000000"/>
    <axis xyz="-0.000000 -0.000000 1.000000"/>
    <limit effort="1" lower="-4.71238898038469" upper="4.71238898038469" velocity="1"/>
    <dynamics damping="0" friction="0"/>
  </joint>

  <link name="J2">
  </link>

  <joint name="joint_2" type="revolute">
    <parent link="J1"/>
    <child link="J2"/>
    <origin rpy="0.000000 0.000000 0.000000" xyz="0.000000 0.000000 0.210000"/>
    <axis xyz="-0.000000 1.000000 -0.000000"/>
    <limit effort="1" lower="-2.61799387799149" upper="2.61799387799149" velocity="1"/>
    <dynamics damping="0" friction="0"/>
  </joint>


  <link name="J3">
  </link>

  <joint name="joint_3" type="revolute">
    <parent link="J2"/>
    <child link="J3"/>
    <origin rpy="0.000000 0.000000 0.000000" xyz="0.000000 0.000000 0.510000"/>
    <axis xyz="-0.000000 1.000000 -0.000000"/>
    <limit effort="1" lower="-2.61799387799149" upper="2.61799387799149" velocity="1"/>
    <dynamics damping="0" friction="0"/>
  </joint>



  <link name="J4">
  </link>

  <joint name="joint_4" type="revolute">
    <parent link="J3"/>
    <child link="J4"/>
    <origin rpy="0.000000 0.000000 0.000000" xyz="0.000000 -0.030000 -0.720000"/>
    <axis xyz="-0.000000 -0.000000 1.000000"/>
    <limit effort="1" lower="-4.71238898038469" upper="4.71238898038469" velocity="1"/>
    <dynamics damping="0" friction="0"/>
  </joint>


  <link name="J5">
  </link>

  <joint name="joint_5" type="revolute">
    <parent link="J4"/>
    <child link="J5"/>
    <origin rpy="0.000000 0.000000 0.000000" xyz="0.000000 0.030000 1.110000"/>
    <axis xyz="-0.000000 1.000000 -0.000000"/>
    <limit effort="1" lower="-2.61799387799149" upper="2.61799387799149" velocity="1"/>
    <dynamics damping="0" friction="0"/>
  </joint>


  <link name="J6">
  </link>

  <joint name="joint_6" type="revolute">
    <parent link="J5"/>
    <child link="J6"/>
    <origin rpy="0.000000 0.000000 0.000000" xyz="0.000000 0.120000 0.160000"/>
    <axis xyz="-0.000000 -0.000000 1.000000"/>
    <limit effort="1" lower="-6.28318530717959" upper="6.28318530717959" velocity="1"/>
    <dynamics damping="0" friction="0"/>
  </joint>



  <link name="onrobot_rg6_base_link">
  </link>

  <link name="left_outer_knuckle">
  </link>

  <link name="left_inner_knuckle">
  </link>

  <link name="left_inner_finger">
  </link>

  <link name="right_outer_knuckle">
  </link>

  <link name="right_inner_knuckle">
  </link>

  <link name="right_inner_finger">
  </link>

  <joint name="finger_joint" type="revolute">
    <origin rpy="0 0 0" xyz="0 -0.024112 0.136813"/>
    <parent link="onrobot_rg6_base_link"/>
    <child link="left_outer_knuckle"/>
    <axis xyz="-1 0 0"/>
    <limit effort="1000" lower="-0.628319" upper="0.628319" velocity="2.0"/>
  </joint>

  <joint name="left_inner_knuckle_joint" type="revolute">
    <origin rpy="0 0 0.0" xyz="0 -0.01272 0.159500"/>
    <parent link="onrobot_rg6_base_link"/>
    <child link="left_inner_knuckle"/>
    <axis xyz="1 0 0"/>
    <limit effort="1000" lower="-0.628319" upper="0.628319" velocity="2.0"/>
    <mimic joint="finger_joint" multiplier="-1" offset="0"/>
  </joint>

  <joint name="left_inner_finger_joint" type="revolute">
    <origin rpy="0 0 0" xyz="0 -0.047334999999999995 0.064495"/>
    <parent link="left_outer_knuckle"/>
    <child link="left_inner_finger"/>
    <axis xyz="1 0 0"/>
    <limit effort="1000" lower="-0.872665" upper="0.872665" velocity="2.0"/>
    <mimic joint="finger_joint" multiplier="1" offset="0"/>
  </joint>

  <joint name="right_outer_knuckle_joint" type="revolute">
    <origin rpy="0 0 3.141592653589793" xyz="0 0.024112 0.136813"/>
    <parent link="onrobot_rg6_base_link"/>
    <child link="right_outer_knuckle"/>
    <axis xyz="1 0 0"/>
    <limit effort="1000" lower="-0.628319" upper="0.628319" velocity="2.0"/>
    <mimic joint="finger_joint" multiplier="-1" offset="0"/>
  </joint>

  <joint name="right_inner_knuckle_joint" type="revolute">
    <origin rpy="0 0 -3.141592653589793" xyz="0 0.01272 0.159500"/>
    <parent link="onrobot_rg6_base_link"/>
    <child link="right_inner_knuckle"/>
    <axis xyz="1 0 0"/>
    <limit effort="1000" lower="-0.628319" upper="0.628319" velocity="2.0"/>
    <mimic joint="finger_joint" multiplier="-1" offset="0"/>
  </joint>

  <joint name="right_inner_finger_joint" type="revolute">
    <origin rpy="0 0 0" xyz="0 -0.047334999999999995 0.064495"/>
    <parent link="right_outer_knuckle"/>
    <child link="right_inner_finger"/>
    <axis xyz="1 0 0"/>
    <limit effort="1000" lower="-0.872665" upper="0.872665" velocity="2.0"/>
    <mimic joint="finger_joint" multiplier="1" offset="0"/>
  </joint>



  <joint name="joint_tcp_fixed" type="fixed">
    <parent link="J6"/>
    <child link="onrobot_rg6_base_link"/>
    <origin rpy="0 0 0" xyz="0 0 0"/>
  </joint>

  <link name="gripper_center"/>
  <joint name="gripper_center_joint" type="fixed">
    <origin rpy="0 0 0" xyz="0.0 0.0 .24"/>
    <parent link="onrobot_rg6_base_link"/>
    <child link="gripper_center"/>
  </joint>
</robot>
