<?xml version="1.0" ?>
<!-- =================================================================================== -->
<!-- |    This document was autogenerated by xacro from cobotta_pro_900_visualization/urdf/cobotta_pro_900.xacro | -->
<!-- |    EDITING THIS FILE BY HAND IS NOT RECOMMENDED                                 | -->
<!-- =================================================================================== -->
<robot name="ur5">
  <link name="world"/>
  <joint name="joint_w" type="fixed">
    <parent link="world"/>
    <child link="ur5_base_link"/>
  </joint>
  
  <link name="ur5_base_link">
    <visual>
      <origin xyz="0 0 0" rpy="0 0 3.141592653589793"/>
      <geometry>
        <mesh filename="package://ur_description/meshes/ur5/visual/base.dae"/>
      </geometry>
      <material name="LightGrey">
        <color rgba="0.7 0.7 0.7 1.0"/>
      </material>
    </visual>
    <collision>
      <origin xyz="0 0 0" rpy="0 0 3.141592653589793"/>
      <geometry>
        <mesh filename="package://ur_description/meshes/ur5/collision/base.stl"/>
      </geometry>
    </collision>
  </link>
  
  <link name="ur5_shoulder_link">
    <visual>
      <origin xyz="0 0 0" rpy="0 0 3.141592653589793"/>
      <geometry>
        <mesh filename="package://ur_description/meshes/ur5/visual/shoulder.dae"/>
      </geometry>
      <material name="LightGrey">
        <color rgba="0.7 0.7 0.7 1.0"/>
      </material>
    </visual>
    <collision>
      <origin xyz="0 0 0" rpy="0 0 3.141592653589793"/>
      <geometry>
        <mesh filename="package://ur_description/meshes/ur5/collision/shoulder.stl"/>
      </geometry>
    </collision>
  </link>
  
  <link name="ur5_upper_arm_link">
      <visual>
      <origin xyz="0 0 0.13585" rpy="1.5707963265 0 -1.5707963265"/>
      <geometry>
        <mesh filename="package://ur_description/meshes/ur5/visual/upperarm.dae"/>
      </geometry>
      <material name="LightGrey">
        <color rgba="0.7 0.7 0.7 1.0"/>
      </material>
    </visual>
    <collision>
      <origin xyz="0 0 0.13585" rpy="1.5707963265 0 -1.5707963265"/>
      <geometry>
        <mesh filename="package://ur_description/meshes/ur5/collision/upperarm.stl"/>
      </geometry>
    </collision>
  </link>
    
  <link name="ur5_forearm_link">
      <visual>
      <origin xyz="0 0 0.0165" rpy="1.5707963265 0 -1.5707963265"/>
      <geometry>
        <mesh filename="package://ur_description/meshes/ur5/visual/forearm.dae"/>
      </geometry>
      <material name="LightGrey">
        <color rgba="0.7 0.7 0.7 1.0"/>
      </material>
    </visual>
    <collision>
      <origin xyz="0 0 0.0165" rpy="1.5707963265 0 -1.5707963265"/>
      <geometry>
        <mesh filename="package://ur_description/meshes/ur5/collision/forearm.stl"/>
      </geometry>
    </collision>
  </link>
    
  <link name="ur5_wrist_1_link">
      <visual>
      <origin xyz="0 0 -0.093" rpy="1.5707963265 0 0"/>
      <geometry>
        <mesh filename="package://ur_description/meshes/ur5/visual/wrist1.dae"/>
      </geometry>
      <material name="LightGrey">
        <color rgba="0.7 0.7 0.7 1.0"/>
      </material>
    </visual>
    <collision>
      <origin xyz="0 0 -0.093" rpy="1.5707963265 0 0"/>
      <geometry>
        <mesh filename= "package://ur_description/meshes/ur5/collision/wrist1.stl"/>
      </geometry>
    </collision>
  </link>
  
  <link name="ur5_wrist_2_link">
      <visual>
      <origin xyz="0 0 -0.095" rpy="0 0 0"/>
      <geometry>
        <mesh filename="package://ur_description/meshes/ur5/visual/wrist2.dae"/>
      </geometry>
      <material name="LightGrey">
        <color rgba="0.7 0.7 0.7 1.0"/>
      </material>
    </visual>
    <collision>
      <origin xyz="0 0 -0.095" rpy="0 0 0"/>
      <geometry>
        <mesh filename="package://ur_description/meshes/ur5/collision/wrist2.stl"/>
      </geometry>
    </collision>
  </link>
    
  <link name="ur5_wrist_3_link">
      <visual>
      <origin xyz="0 0 -0.0818" rpy="1.5707963265 0 0"/>
      <geometry>
        <mesh filename="package://ur_description/meshes/ur5/visual/wrist3.dae"/>
      </geometry>
      <material name="LightGrey">
        <color rgba="0.7 0.7 0.7 1.0"/>
      </material>
    </visual>
    <collision>
      <origin xyz="0 0 -0.0818" rpy="1.5707963265 0 0"/>
      <geometry>
        <mesh filename="package://ur_description/meshes/ur5/collision/wrist3.stl"/>
      </geometry>
    </collision>
  </link>
    
  <joint name="ur5_ee_fixed_joint" type="fixed">
    <parent link="ur5_wrist_3_link" />
    <child link = "ur5_ee_link" />
    <!-- Корректировка offset гриппера -->
    <origin xyz="0 0 0.015" rpy="0 -1.5707963265 0" />
  </joint>

  <link name="ur5_ee_link">
    <collision>
      <geometry>
        <box size="0.01 0.01 0.01"/>
      </geometry>
      <origin rpy="0 0 0" xyz="-0.01 0 0"/>
    </collision>
  </link>

    <link name="ur5_tool0"/>
    <joint name="ur5_wrist_3_link-tool0_fixed_joint" type="fixed">
      <origin xyz="0 0 0" rpy="-1.5707963265 0 0"/>
      <parent link="ur5_wrist_3_link"/>
      <child link="ur5_tool0"/>
    </joint>
  
  <joint name="ur5_shoulder_pan_joint" type="revolute">
    <parent link="ur5_base_link"/>
    <child link="ur5_shoulder_link"/>
    <origin rpy="0.000000 0.000000 0.000000" xyz="0.000000 0.000000 0.089159"/>
    <axis xyz="0 0 1"/>
    <limit effort="150" lower="-6.28318530717959" upper="6.28318530717959" velocity="3.141592653589793"/>
    <dynamics damping="0" friction="0"/>
  </joint>
    

  
  <joint name="ur5_shoulder_lift_joint" type="revolute">
    <parent link="ur5_shoulder_link"/>
    <child link="ur5_upper_arm_link"/>
    <origin rpy="1.570796327 0.000000 0.000000" xyz="0.000000 0.000000 0"/>
    <axis xyz="0 0 1"/>
    <limit effort="150" lower="-6.28318530717959" upper="6.28318530717959" velocity="3.141592653589793"/>
    <dynamics damping="0" friction="0"/>
  </joint>
  

  
  <joint name="ur5_elbow_joint" type="revolute">
    <parent link="ur5_upper_arm_link"/>
    <child link="ur5_forearm_link"/>
    <origin rpy="0.000000 0.000000 0.000000" xyz="-0.425 0.000000 0"/>
    <axis xyz="0 0 1"/>
    <limit effort="150" lower="-3.141592653589793" upper="3.141592653589793" velocity="3.141592653589793"/>
    <dynamics damping="0" friction="0"/>
  </joint>
  

  
  <joint name="ur5_wrist_1_joint" type="revolute">
    <parent link="ur5_forearm_link"/>
    <child link="ur5_wrist_1_link"/>
    <origin rpy="0.000000 0.000000 0.000000" xyz="-0.39225 0 0.10915"/>
    <axis xyz="0 0 1"/>
    <limit effort="28" lower="-6.28318530717959" upper="6.28318530717959" velocity="3.141592653589793"/>
    <dynamics damping="0" friction="0"/>
  </joint>
  
    

  
  <joint name="ur5_wrist_2_joint" type="revolute">
    <parent link="ur5_wrist_1_link"/>
    <child link="ur5_wrist_2_link"/>
    <origin rpy="1.570796327 0 0" xyz="0 -0.09465 -1.941303950897609e-11"/>
    <axis xyz="0 0 1"/>
    <limit effort="28" lower="-6.28318530717959" upper="6.28318530717959" velocity="3.141592653589793"/>
    <dynamics damping="0" friction="0"/>
  </joint>
  

  
  <joint name="ur5_wrist_3_joint" type="revolute">
    <parent link="ur5_wrist_2_link"/>
    <child link="ur5_wrist_3_link"/>
    <origin rpy="1.570796326589793 3.141592653589793 3.141592653589793" xyz="0 0.0823 -1.688001216681175e-11"/>
    <axis xyz="0 0 1"/>
    <limit effort="28" lower="-6.28318530717959" upper="6.28318530717959" velocity="3.141592653589793"/>
    <dynamics damping="0" friction="0"/>
  </joint>
  



  
</robot>
